Workbook

Sheet 产品品质履历卡
B1: W10551273产品品质履历卡
B2: § | C2: 计划 | I2: 实施 | J2: 检查 | K2: 标准化
C3: 问题点 | D3: 原因分析 | E3: 改进行动 | F3: 负责人 | G3: 实施日期) | H3: 完成日期 | I3: 实施状态 | J3: 验证结果 | K3: 永久措施有效性
B4: 一.工程样品问题点:
B5: 1
B6: 2
B7: 二.PPAP过程审核：
B8: 1
B9: 2
B10: 三.客户投诉问题点：
B11: 1
B12: 2
B13: 四.验货发现问题点：
B14: 1
B15: 2
C16: 起草: | E16: 审核: | F16: 批准:

Sheet Product Summary 
A1: 出货检验报告总汇
A3: 序号 | B3: 名称 | C3: 部件号 | D3: 合同号 | E3: 部件总数(pcs) | F3: 箱数(ctn) | G3: 托数(Pallet) | H3: 抽检数(pcs) | I3: 不合格数(pcs) | J3: 检验情况 | M3: 个人意见 | N3: 公司意见 | O3: 批次 | P3: 备注 | Q3: ERP No.
A4: 1 | B4: PLATE WHITE VMW MX | C4: W10551273 | D4: 1510001016 | E4: 10800 | F4: 6 | G4: 1 | H4: 315 | I4: 0 | J4: 抽检315PCS产品符合出货检验规范要求,但发现有一箱少装一盒产品,更改后OK | M4: 可以出货 | O4: IUH173J262AA1023 W20171025 | P4: First | Q4: 1510000652
H7: Inspector: | L7: Luanmei | M7: Date: | N7: 43033

Sheet W10551273
A1:  | C1: FINAL OUTPUT INSPECTION REPORT(出货检验报告） | N1: R020 Rev.5
A3: PART NAME（部件名称）: | C3: PLATE WHITE VMW MX | F3: CUSTOMER（客户） | H3: Whirlpool | K3: PRODUCTION DATE(生产日期) | N3: 2017-10-7～2017-10-22
A4: PART No. （部件号）： | C4: W10551273 | F4: PO No.（合同号）： | H4: ='Product Summary '!D4 -> 1510001016 | K4: INSPECTION DATE(验货日期) | N4: 43033
A5: DWG No. (图纸号): | C5: W10551270 | F5: BATCH No.(批次号): | H5: ='Product Summary '!O4 -> IUH173J262AA1023 W20171025 | K5: INSPECTED BY (检查者): | N5: luanmei
A6: ERP. No.(编号） | C6: 1010001966 | F6: SUPPLIER （供应商）： | H6: ZT | K6: TOTAL PRODUCT QUANTITY(產品数量): | N6: 10800 | O6: pcs
A7: INSPECT STANDARD(检验标准）： | C7: GB/T2828.1:2012 | F7: AQL Level(AQL 水平） | H7: 0.065 | K7: TOTAL PACKAGE QUANTITY(箱子数量): | N7: =N6/1800 -> 6 | O7: Carton
A8: INSPECT LEVEL（检验水平）: | C8: Ⅰ | E8: Accept Qty (接收数): | G8: 0 | H8: Reject Qty(不接受数) : | J8: 1 | K8: SAMPLING SIZE (抽样数) : | M8: 315pcs | N8: Ins Time | O8: First
A9: DOCUMENTS CHECK(文件审查)
A10: Supplier & date of material (原材料厂家和出厂日期): | C10: See the Material test certificate attachment | G10: Equipment of performance test (性能测试设备): | J10: Salt Spray test (盐雾测试) | L10: Strength test (强度测试） | N10: NA
A11: Component of material (原材料成分): | C11: See the Material test certificate attachment SUS103 1/2H and ZAMAK5(ZnAl4Cu1) | G11: Date of performance test (性能测试时间): | J11: NA | L11: NA | N11: NA
A12: Performance data of material (原材料的性能数据): | C12: See the Material test certificate attachment | G12: Results of performance test (性能测试结果): | J12: NA | L12: NA | N12: NA
A13: ACTUAL SAMPLING CHECK OF CRITICAL REQUIREMENT(实际抽样检查表)
A14: Original test record (原始检测记录）：
A15: Inspection Item | E15: Inspection Detail
A16: Sampling Standard(规格) | C16: Upp Spec | D16: Low Spec | E16: Material Data | O16: Max Diff.
C17: Limit | D17: Limit | E17: Sample #1 | F17: Sample #2 | G17: Sample #3 | H17: Sample #4 | I17: Sample #5 | J17: Sample #6 | K17: Sample #7 | L17: Sample #8 | M17: Sample #9 | N17: Sample #10 | O17: From Spec
A18: No | B18: Drawing Spec(图纸规格） | C18: 规格上限 | D18: 规格下限 | E18: 样品1 | F18: 样品2 | G18: 样品3 | H18: 样品4 | I18: 样品5 | J18: 样品6 | K18: 样品7 | L18: 样品8 | M18: 样品9 | N18: 样品10 | O18: 最大偏差
A19: 1 | B19: 产品喷涂后，无伤痕,无毛刺，无露点 | E19: Pass | F19: Pass | G19: Pass | H19: Pass | I19: Pass | J19: Pass | K19: Pass | L19: Pass | M19: Pass | N19: Pass
A20: 2 | B20: 22.35+/-0.15mm | C20: =22.35+0.15 -> 22.5 | D20: =22.35-0.15 -> 22.2 | E20: 22.42 | F20: 22.45 | G20: 22.42 | H20: 22.43 | I20: 22.42 | J20: 22.44 | K20: 22.43 | L20: 22.46 | M20: 22.43 | N20: 22.43
A21: 3 | B21: 8+/-0.15mm | C21: =8+0.15 -> 8.15 | D21: =8-0.15 -> 7.85 | E21: 7.95 | F21: 7.97 | G21: 7.9 | H21: 7.91 | I21: 7.93 | J21: 7.94 | K21: 7.91 | L21: 7.92 | M21: 7.99 | N21: 7.91
A22: 4 | B22: 10.65+/-0.15mm | C22: =10.65+0.15 -> 10.8 | D22: =10.65-0.15 -> 10.5 | E22: 10.56 | F22: 10.53 | G22: 10.62 | H22: 10.58 | I22: 10.57 | J22: 10.57 | K22: 10.57 | L22: 10.62 | M22: 10.63 | N22: 10.57
A23: 5 | B23: 膜厚 50-100um | C23: =100 -> 100 | D23: =50 -> 50 | E23: 55 | F23: 55 | G23: 63 | H23: 59 | I23: 56.7 | J23: 57 | K23: 55.9 | L23: 56.8 | M23: 57.6 | N23: 56.3
A24: 6 | B24: Φ5.15+/-0.15mm | C24: =5.15+0.15 -> 5.3 | D24: =5.15-0.15 -> 5 | E24: 5.24 | F24: 5.23 | G24: 5.24 | H24: 5.28 | I24: 5.2 | J24: 5.19 | K24: 5.21 | L24: 5.2 | M24: 5.23 | N24: 5.21
A25: 7 | B25: 100.15+/-0.15mm | C25: =100.15+0.15 -> 100.3 | D25: =100.15-0.15 -> 100 | E25: 100.02 | F25: 100.03 | G25: 100.03 | H25: 100.01 | I25: 100.07 | J25: 100.02 | K25: 100.04 | L25: 100.08 | M25: 100.04 | N25: 100.06
A26: 8 | B26: 15+/-0.1mm | C26: =15+0.1 -> 15.1 | D26: =15-0.1 -> 14.9 | E26: 14.95 | F26: 15.02 | G26: 15 | H26: 15.01 | I26: 14.97 | J26: 15.04 | K26: 14.95 | L26: 15 | M26: 14.96 | N26: 14.97
A27: 9 | B27: 其它（Other）
A28: 10
A29: 11
A30: PACKAGING CHECK(包装检查)
A31: Packaging method(包装方式): | C31: See The Photos. | F31: Carton Label(标签) | H31: See the photo | K31: Qty per pallet(每棧板数量): | N31: 32CTN/Pallet
A32: Carton seal Method(密封方式） | C32: N/A(not yet pasted) | F32: Package status(包装外观) | H32: See the photo | K32: Qty per carton(每箱数量): | N32: 1800pcs,(50pcs/box,36box/CTN)
A33: Inspection Result(检验结果） Pass(可以接受） Fail(不可接受） reference （参考）
A34: ='Product Summary '!J4 -> 抽检315PCS产品符合出货检验规范要求,但发现有一箱少装一盒产品,更改后OK
J35: SIGNATURE(签名): | L35: luanmei | N35: DATE(时间) | O35: ='Product Summary '!N7 -> 43033
A36: CHECKING RESULT/COMMENTS(核查结果):
J38: CHECKED BY(审核者) | N38: DATE(时间)
A39: CHECKING RESULT/COMMENTS(核查结果):
J41: CHECKED BY(审核者) | N41: DATE(时间)
A42: CHECKING RESULT/COMMENTS(核查结果):
J44: CHECKED BY(审核者) | N44: DATE(时间)
...

Sheet 量产产品状况清单
A1: 量产产品状况检查单
A2: No | B2: 产品编号 | C2: PPAP样品 | D2: 最新签样 | E2: 客户承认PPAP资料 | F2: 工厂PSW | G2: 工厂SOP | H2: 工厂SIP | I2: 受控图纸 | J2: 出货检验规范 | K2: 通用外观 标准
A3: 2 | B3: W10551273 | C3: 无最新签样 | D3: 无最新签样 | E3: 有收到相关资料 | F3: 有收到相关资料 | G3: 有收到相关资料 | H3: 有收到相关资料 | I3: 有收到相关资料 | J3: 有收到相关资料 | K3: 有收到相关资料

Sheet 产品图纸

Sheet Sheet1
A1: 产品质量审核报告
A3: 零件号: | B3: =[1]审核报告!B4 -> W10551273 | C3: 零件名称 | D3: =[1]审核报告!J4 -> plate | F3: 图纸号及 版本号 | H3: W10551273 | J3: B
A4: 取样日期 | B4: =[1]审核报告!B5 -> 42935 | C4: 取样地点 | D4: =[1]审核报告!J5 -> 库房 | F4: 生产日期: | H4: N/A
A5: 产品外形尺寸图示： 备注：先查询该零件号是否提交过PPAP，如有，则采用顾客批准的外形尺寸图；如无，则依照产品企业标准。
A8: 编号 标准 | B8: 1 | C8: 2 | D8: 3 | L8: 测量仪器 | M8: UNITS | N8: Remark | O8: 最小值 | P8: 最大值 | Q8: 模具履历卡
A9: 10.50±0.10 | B9: 10.5 | C9: 10.49 | D9: 10.52 | L9: 卡尺 | M9: mm | N9: 宽度 | O9: =MIN(B9:N9) -> 10.49 | P9: =MAX(B9:N9) -> 10.52
A10: 4x 5.30±0.10 | B10: 5.35 | C10: 5.36 | D10: 5.34 | L10: 投影仪 | M10: mm | N10: 孔径 | O10: =MIN(B10:N10) -> 5.34 | P10: =MAX(B10:N10) -> 5.36
B11: 0.01 | C11: 0.02 | D11: 0.01 | L11: 投影仪 | M11: mm | N11: 位置度 | O11: =MIN(B11:N11) -> 0.01 | P11: =MAX(B11:N11) -> 0.02
A12: 100.00±0.10 | B12: 100 | C12: 100.05 | D12: 100.02 | L12: 卡尺 | M12: mm | N12: 总长 | O12: =MIN(B12:N12) -> 100 | P12: =MAX(B12:N12) -> 100.05
A13: 22.50±0.10 | B13: 22.52 | C13: 22.54 | D13: 22.55 | L13: 卡尺 | M13: mm | N13: 开口宽 | O13: =MIN(B13:N13) -> 22.52 | P13: =MAX(B13:N13) -> 22.55
A14: 8.00±0.10 | B14: 8.02 | C14: 8.03 | D14: 8.05 | L14: 卡尺 | M14: mm | N14: 开口高 | O14: =MIN(B14:N14) -> 8.02 | P14: =MAX(B14:N14) -> 8.05
A15: 1.00±0.04 | B15: 1.04 | C15: 1.03 | D15: 1.02 | L15: 卡尺 | M15: mm | N15: 料厚 | O15: =MIN(B15:N15) -> 1.02 | P15: =MAX(B15:N15) -> 1.04
A16: NOTE.1 | B16: OK | C16: OK | D16: OK | O16: =MIN(B16:N16) -> 0 | P16: =MAX(B16:N16) -> 0
A17: NOTE.2 | B17: OK | C17: OK | D17: OK | O17: =MIN(B17:N17) -> 0 | P17: =MAX(B17:N17) -> 0
A18: NOTE.3 | B18: OK | C18: OK | D18: OK | O18: =MIN(B18:N18) -> 0 | P18: =MAX(B18:N18) -> 0
A19: NOTE.4 | B19: OK | C19: OK | D19: OK
A20: NOTE.5 | B20: OK | C20: OK | D20: OK
A21: NOTE.6 | B21: OK | C21: OK | D21: OK
A22: NOTE.7 | B22: OK | C22: OK | D22: OK
A23: NOTE.8 | B23: OK | C23: OK | D23: OK
A24: NOTE.9 | B24: OK | C24: OK | D24: OK
A25: NOTE.10 | B25: OK | C25: OK | D25: OK | O25: =MIN(B25:N25) -> 0 | P25: =MAX(B25:N25) -> 0
O26: =MIN(B26:N26) -> 0 | P26: =MAX(B26:N26) -> 0
